Workbook

Sheet Dashboard
B1: PPC Optimizer — Campaign Dashboard
B2: Generated 2026-07-20 · 5533 products · 3 campaign(s)
B4: TOTAL PRODUCTS | F4: TOTAL COST | J4: TOTAL REVENUE | N4: OVERALL ROAS
B5: =COUNTA(Products!$D$2:$D$5534) | F5: =SUM(Products!$J$2:$J$5534) | J5: =SUM(Products!$L$2:$L$5534) | N5: =IFERROR(SUM(Products!$L$2:$L$5534)/SUM(Products!$J$2:$J$5534),0)
B8: KEEP | F8: WATCH | J8: PAUSE | N8: SCALE
B9: =COUNTIF(Products!$U$2:$U$5534,"KEEP") | F9: =COUNTIF(Products!$U$2:$U$5534,"WATCH") | J9: =COUNTIF(Products!$U$2:$U$5534,"PAUSE") | N9: =COUNTIF(Products!$U$2:$U$5534,"SCALE")
B12: WASTED SPEND (PAUSE) | F12: SCALE REVENUE | J12: TOTAL CONVERSIONS | N12: CAMPAIGN HEALTH
B13: =SUMIFS(Products!$J$2:$J$5534,Products!$U$2:$U$5534,"PAUSE") | F13: =SUMIFS(Products!$L$2:$L$5534,Products!$U$2:$U$5534,"SCALE") | J13: =SUM(Products!$K$2:$K$5534) | N13: Needs attention
B16: Campaign Comparison
B17: Campaign | C17: Products | D17: Cost | E17: Revenue | F17: ROAS | G17: Scale | H17: Pause | I17: Health
B18: high_price | C18: =COUNTIF(Products!$A$2:$A$5534,"high_price") | D18: =SUMIFS(Products!$J$2:$J$5534,Products!$A$2:$A$5534,"high_price") | E18: =SUMIFS(Products!$L$2:$L$5534,Products!$A$2:$A$5534,"high_price") | F18: =IFERROR(E18/D18,0) | G18: =COUNTIFS(Products!$A$2:$A$5534,"high_price",Products!$U$2:$U$5534,"SCALE") | H18: =COUNTIFS(Products!$A$2:$A$5534,"high_price",Products!$U$2:$U$5534,"PAUSE") | I18: Needs attention
B19: average_price | C19: =COUNTIF(Products!$A$2:$A$5534,"average_price") | D19: =SUMIFS(Products!$J$2:$J$5534,Products!$A$2:$A$5534,"average_price") | E19: =SUMIFS(Products!$L$2:$L$5534,Products!$A$2:$A$5534,"average_price") | F19: =IFERROR(E19/D19,0) | G19: =COUNTIFS(Products!$A$2:$A$5534,"average_price",Products!$U$2:$U$5534,"SCALE") | H19: =COUNTIFS(Products!$A$2:$A$5534,"average_price",Products!$U$2:$U$5534,"PAUSE") | I19: Needs attention
B20: low_price | C20: =COUNTIF(Products!$A$2:$A$5534,"low_price") | D20: =SUMIFS(Products!$J$2:$J$5534,Products!$A$2:$A$5534,"low_price") | E20: =SUMIFS(Products!$L$2:$L$5534,Products!$A$2:$A$5534,"low_price") | F20: =IFERROR(E20/D20,0) | G20: =COUNTIFS(Products!$A$2:$A$5534,"low_price",Products!$U$2:$U$5534,"SCALE") | H20: =COUNTIFS(Products!$A$2:$A$5534,"low_price",Products!$U$2:$U$5534,"PAUSE") | I20: Needs attention
B22: Budget Optimization
B23: Campaign | C23: Current Spend | D23: ROAS | E23: Recommendation | F23: Move Budget | G23: Expected Gain
B24: high_price | C24: =SUMIFS(Products!$J$2:$J$5534,Products!$A$2:$A$5534,"high_price") | D24: =IFERROR(SUMIFS(Products!$L$2:$L$5534,Products!$A$2:$A$5534,"high_price")/SUMIFS(Products!$J$2:$J$5534,Products!$A$2:$A$5534,"high_price"),0) | E24: KEEP | F24: 0 | G24: 0
B25: average_price | C25: =SUMIFS(Products!$J$2:$J$5534,Products!$A$2:$A$5534,"average_price") | D25: =IFERROR(SUMIFS(Products!$L$2:$L$5534,Products!$A$2:$A$5534,"average_price")/SUMIFS(Products!$J$2:$J$5534,Products!$A$2:$A$5534,"average_price"),0) | E25: KEEP | F25: 0 | G25: 0
B26: low_price | C26: =SUMIFS(Products!$J$2:$J$5534,Products!$A$2:$A$5534,"low_price") | D26: =IFERROR(SUMIFS(Products!$L$2:$L$5534,Products!$A$2:$A$5534,"low_price")/SUMIFS(Products!$J$2:$J$5534,Products!$A$2:$A$5534,"low_price"),0) | E26: INCREASE | F26: 0 | G26: 0
B27: Expected total gain | G27: 0

Sheet Executive Summary
B1: Executive Summary
B2: Generated 2026-07-20
B4: Campaign health | D4: Needs attention
B6: Products analyzed | D6: =COUNTA(Products!$D$2:$D$5534)
B7: Total advertising cost | D7: =SUM(Products!$J$2:$J$5534)
B8: Total conversion value | D8: =SUM(Products!$L$2:$L$5534)
B9: Overall ROAS | D9: =IFERROR(SUM(Products!$L$2:$L$5534)/SUM(Products!$J$2:$J$5534),0)
B10: Wasted spend (PAUSE products) | D10: =SUMIFS(Products!$J$2:$J$5534,Products!$U$2:$U$5534,"PAUSE")
B11: Revenue from SCALE products | D11: =SUMIFS(Products!$L$2:$L$5534,Products!$U$2:$U$5534,"SCALE")
B13: 3 of 3 campaign(s) need attention.
B15: Recommended actions per campaign
B17: high_price (High priority, high_price.csv) — Needs attention
B18: • Pause or fix products with clicks but no sales.
B19: • Improve titles, images, or bids for products without clicks.
B20: • Improve listings or targeting for low-CTR products.
B21: • Review bids for products with above-average CPC.
B22: • Consider increasing budget for high-ROAS products.
B24: average_price (Medium priority, average_price.csv) — Needs attention
B25: • Pause or fix products with clicks but no sales.
B26: • Review products without impressions for eligibility issues.
B27: • Improve titles, images, or bids for products without clicks.
... B41: • No budget redistribution recommended — the current allocation is balanced.

Sheet Products
A1: Campaign | B1: Campaign Type | C1: Source File | D1: Product ID | E1: Product | F1: Clicks | G1: Impressions | H1: CTR | I1: Avg. CPC | J1: Cost | K1: Conversions | L1: Conversion Value | M1: Cost / Conv. | N1: All Conversions | O1: All Conv. Value | P1: Зображення | Q1: Статус | R1: Проблеми | S1: Ціна | T1: Код валюти | U1: Status | V1: ROAS | W1: Recommendation | X1: Reason
A2: high_price | B2: High priority | C2: high_price.csv | D2: 13031-0983 | E2: Колінвал Kawasaki Teryx 800​ 2014+ | F2: 0 | G2: 249 | H2: 0 | I2: 0 | J2: 0 | K2: 0 | L2: 0 | M2: 0 | N2: 0 | O2: 0 | P2: http://t0.gstatic.com/shopping?q=tbn:ANd9GcRVXppgcwWiKujQ6OvKi1I6tyv27DzQx9Vhgux920LHYOBggjVqfCsIbvdymwiL7LTSl9qvAiI | Q2: Відповідає вимогам | S2: грн34 034,00 | T2: UAH | U2: WATCH | V2: =IFERROR(L2/J2,0) | W2: Monitor performance and collect more data. | X2: Cost is below the 300 watch threshold.
A3: high_price | B3: High priority | C3: high_price.csv | D3: 715009472 | E3: Кофр LinQ для BRP Can-Am Outlander G3 G3L (139L) | F3: 35 | G3: 2860 | H3: 1.22 | I3: 11.23 | J3: 392.91 | K3: 0 | L3: 0 | M3: 0 | N3: 8.21 | O3: 207156.7 | P3: http://t3.gstatic.com/shopping?q=tbn:ANd9GcQAUVYXTrpeU8suNkUvfGUR3oN12pZiQDTYWKS5XJtPIO_6eicblJQDfIL-Oh_REbjRNy8OzrJa | Q3: Відповідає вимогам | S3: грн35 399,00 | T3: UAH | U3: WATCH | V3: =IFERROR(L3/J3,0) | W3: Monitor performance and collect more data. | X3: Performance is below the scale and keep thresholds.
A4: high_price | B4: High priority | C4: high_price.csv | D4: 420219746 | E4: Колінвал BRP Can-Am Outlander 570 650 800 850, Renegade 650 800 850, Commander 800 | F4: 0 | G4: 2461 | H4: 0 | I4: 0 | J4: 0 | K4: 0 | L4: 0 | M4: 0 | N4: 0 | O4: 0 | P4: http://t2.gstatic.com/shopping?q=tbn:ANd9GcSyZxy7BIYHEDXwXVueQa0QBKQa3GHlSSabmk2PYO7qJTDEpRXBX4kRTPhmAO-vVbPn-PJvHF8p | Q4: Відповідає вимогам | S4: грн34 808,00 | T4: UAH | U4: WATCH | V4: =IFERROR(L4/J4,0) | W4: Monitor performance and collect more data. | X4: Cost is below the 300 watch threshold.
A5: high_price | B5: High priority | C5: high_price.csv | D5: 715007110 | E5: Комплект шноркеля BRP Can-Am Maverick X3 2020+ | F5: 124 | G5: 35430 | H5: 0.35 | I5: 5.33 | J5: 661.32 | K5: 0 | L5: 0 | M5: 0 | N5: 0.5 | O5: 13400 | P5: http://t0.gstatic.com/shopping?q=tbn:ANd9GcSIbO0yt3Yjs85QulMTCeMRwdBz6EZFQTv_SdQka7tjj43FUJUX0chtFsf0rA | Q5: Відповідає вимогам | S5: грн47 912,00 | T5: UAH | U5: WATCH | V5: =IFERROR(L5/J5,0) | W5: Monitor performance and collect more data. | X5: Performance is below the scale and keep thresholds.
A6: high_price | B6: High priority | C6: high_price.csv | D6: 715005481 | E6: Глушник Yoshimura для BRP Can-Am Renegade G2S | F6: 38 | G6: 13300 | H6: 0.29 | I6: 7.28 | J6: 276.76 | K6: 0.96 | L6: 4201.38 | M6: 287.54 | N6: 2.96 | O6: 4201.38 | P6: http://t2.gstatic.com/shopping?q=tbn:ANd9GcQEVmOmNieD8fFQXIbEQ6vy51QnWNguQfb_FLLLwFyVgV4v7opNZNDqOVJZios9EH0rnOEpgTaF | Q6: Відповідає вимогам | S6: грн57 922,00 | T6: UAH | U6: WATCH | V6: =IFERROR(L6/J6,0) | W6: Monitor performance and collect more data. | X6: Cost is below the 300 watch threshold.
A7: high_price | B7: High priority | C7: high_price.csv | D7: 709401608 | E7: Підсилювач керма BRP Can-Am Outlander Renegade G1 G2 G2L G2S 2010-2017 | F7: 19 | G7: 1134 | H7: 1.68 | I7: 3.61 | J7: 68.52 | K7: 1 | L7: 62017 | M7: 68.52 | N7: 4.3 | O7: 266370.52 | P7: http://t1.gstatic.com/shopping?q=tbn:ANd9GcSXN22QLJGlQxzvQq3zddgx0dh9YhpRj3Fnn07d-x9PasmqifRZoHqLGFw3ICDJTP7NO8R7MFXw | Q7: Відповідає вимогам | S7: грн62 017,00 | T7: UAH | U7: WATCH | V7: =IFERROR(L7/J7,0) | W7: Monitor performance and collect more data. | X7: Cost is below the 300 watch threshold.
A8: high_price | B8: High priority | C8: high_price.csv | D8: 12100-hr0-f00 | E8: Циліндр двигуна Honda TRX 500 Foreman (12-19), 500 Rubicon (15-19), SXS 500 Pioneer (15+) | F8: 0 | G8: 15 | H8: 0 | I8: 0 | J8: 0 | K8: 0 | L8: 0 | M8: 0 | N8: 0 | O8: 0 | P8: http://t0.gstatic.com/shopping?q=tbn:ANd9GcQM2suQNgasT5-OSFk1DsplU_UTMxuRfqgYay4ZXK_5yZsRzU-JzOyEuny3q1amfX68o2A1tsVU | Q8: Відповідає вимогам | S8: грн30 167,00 | T8: UAH | U8: WATCH | V8: =IFERROR(L8/J8,0) | W8: Monitor performance and collect more data. | X8: Cost is below the 300 watch threshold.
A9: high_price | B9: High priority | C9: high_price.csv | D9: 707602827 | E9: Глушник BRP Can-Am Maverick X3 | F9: 8 | G9: 7224 | H9: 0.11 | I9: 6.72 | J9: 53.76 | K9: 0 | L9: 0 | M9: 0 | N9: 0 | O9: 0 | P9: http://t3.gstatic.com/shopping?q=tbn:ANd9GcTnccq_eOG2k29nGi5aGy_6Suf8hG4gVXi-iytjnrJIp4oMvD_Tx2t1W7J_6btPlei5Yy3420oe | Q9: Відповідає вимогам | S9: грн42 042,00 | T9: UAH | U9: WATCH | V9: =IFERROR(L9/J9,0) | W9: Monitor performance and collect more data. | X9: Cost is below the 300 watch threshold.
A10: high_price | B10: High priority | C10: high_price.csv | D10: 12200-hn5-m00 | E10: Головка блоку циліндра Honda TRX 350 Rancher 2003-2006 | F10: 2 | G10: 330 | H10: 0.61 | I10: 9.19 | J10: 18.38 | K10: 0 | L10: 0 | M10: 0 | N10: 0 | O10: 0 | P10: http://t0.gstatic.com/shopping?q=tbn:ANd9GcRKJ6G3_Qt_FgTtfkVagRFmZPiRtWbnmujnuQYJEP5mNpKRtfe47O0mnVrU63wfahjwBFfdbl4 | Q10: Відповідає вимогам | S10: грн31 031,00 | T10: UAH | U10: WATCH | V10: =IFERROR(L10/J10,0) | W10: Monitor performance and collect more data. | X10: Cost is below the 300 watch threshold.
A11: high_price | B11: High priority | C11: high_price.csv | D11: 26000-hl1-a01 | E11: Гідротрансформатор Honda TRX 680 Rincon, MUV 700 Big Red, SXS 700 Pioneer | F11: 0 | G11: 78 | H11: 0 | I11: 0 | J11: 0 | K11: 0 | L11: 0 | M11: 0 | N11: 0 | O11: 0 | P11: http://t0.gstatic.com/shopping?q=tbn:ANd9GcSu9JaWEifiFhLiIQKB8TpRuaXbO5gSNV52ohuTN_BD1NGLhTdXS8ZFWk1lahfjIbFkzLYYdcc | Q11: Відповідає вимогам | S11: грн57 603,00 | T11: UAH | U11: WATCH | V11: =IFERROR(L11/J11,0) | W11: Monitor performance and collect more data. | X11: Cost is below the 300 watch threshold.
A12: high_price | B12: High priority | C12: high_price.csv | D12: 715008859 | E12: Вітрове скло BRP Can-Am Maverick X3 | F12: 44 | G12: 5078 | H12: 0.87 | I12: 1.34 | J12: 58.81 | K12: 0 | L12: 0 | M12: 0 | N12: 0 | O12: 0 | P12: http://t3.gstatic.com/shopping?q=tbn:ANd9GcTYh4tXfIchMRYEZHJqrtXhqpcQYCa2ar_7KAqsRiEWjOglE8js7HEtA82OFvs5O5NVWAye5lw | Q12: Відповідає вимогам | S12: грн68 432,00 | T12: UAH | U12: WATCH | V12: =IFERROR(L12/J12,0) | W12: Monitor performance and collect more data. | X12: Cost is below the 300 watch threshold.
A13: high_price | B13: High priority | C13: high_price.csv | D13: 706202170 | E13: Амортизатор передній BRP Can-Am Outlander XMR 570 650 850 1000 2015-2016 | F13: 9 | G13: 3092 | H13: 0.29 | I13: 4.65 | J13: 41.83 | K13: 0 | L13: 0 | M13: 0 | N13: 0 | O13: 0 | P13: http://t3.gstatic.com/shopping?q=tbn:ANd9GcSJ8vO2fhfpupsSgk3yzidsx9YKXotBWW7anCA-M3MPf-PYbsFLgHmE2q9GbCQBOtgKgxvPuvrH | Q13: Відповідає вимогам | S13: грн42 088,00 | T13: UAH | U13: WATCH | V13: =IFERROR(L13/J13,0) | W13: Monitor performance and collect more data. | X13: Cost is below the 300 watch threshold.
... A164: average_price | B164: Medium priority | C164: average_price.csv | D164: 44250-hr4-a22 | E164: Кулак передній зовнішній правий Honda TRX 500 Foreman (14-19), 500 Rubicon (15-16) | F164: 1 | G164: 70 | H164: 1.43 | I164: 12.35 | J164: 12.35 | K164: 0 | L164: 0 | M164: 0 | N164: 0 | O164: 0 | P164: http://t3.gstatic.com/shopping?q=tbn:ANd9GcTwqdrMlRcEMkQcvRJDsFOj6SCP1tJZtSIeMLH9gbcmvynDM7sof5MA-7FCRM_XLJb7zVNNZQ | Q164: Відповідає вимогам | S164: грн11 466,00 | T164: UAH | U164: WATCH | V164: =IFERROR(L164/J164,0) | W164: Monitor performance and collect more data. | X164: Cost is below the 250 watch threshold.
A165: average_price | B165: Medium priority | C165: average_price.csv | D165: 715007378 | E165: Світлодіодна балка SMART на капот BRP Can-Am Maverick R | F165: 0 | G165: 0 | I165: 0 | J165: 0 | K165: 0 | L165: 0 | M165: 0 | N165: 0 | O165: 0 | P165: http://t2.gstatic.com/shopping?q=tbn:ANd9GcRvQmQHvgtr84YjWZ9QQCaVbdYqFZKrJGge4iC2cgtPLLZ2tyNwdtb4XfHKaPg | Q165: Відповідає вимогам | S165: грн20 703,00 | T165: UAH | U165: WATCH | V165: =IFERROR(L165/J165,0) | W165: Monitor performance and collect more data. | X165: Cost is below the 250 watch threshold.
A166: average_price | B166: Medium priority | C166: average_price.csv | D166: ab8-ca-8-127 | E166: Посилена піввісь передня BRP Can-Am Maverick X3 72" | F166: 6 | G166: 155 | H166: 3.87 | I166: 9.63 | J166: 57.79 | K166: 0 | L166: 0 | M166: 0 | N166: 0 | O166: 0 | P166: http://t2.gstatic.com/shopping?q=tbn:ANd9GcTcJvGSRMFUsscTyBHjDY2b3cpbopkK9dOJv5eoSsaHZMQ92hGm5okk6LIh0zoISorWefL_2cye | Q166: Відповідає вимогам | S166: грн12 285,00 | T166: UAH | U166: WATCH | V166: =IFERROR(L166/J166,0) | W166: Monitor performance and collect more data. | X166: Cost is below the 250 watch threshold.
A167: average_price | B167: Medium priority | C167: average_price.csv | D167: 3233854 | E167: Шестерня КПП Polaris Sportsman 400 450 500 570 600 700 800, Magnum 330 500, ACE 325 570 (24T) | F167: 0 | G167: 13 | H167: 0 | I167: 0 | J167: 0 | K167: 0 | L167: 0 | M167: 0 | N167: 0 | O167: 0 | P167: http://t0.gstatic.com/shopping?q=tbn:ANd9GcRukVgdxzvYxfUZtZ46Fn_H8xw0kPngVT2vXDvVMQ9gIItIhF1XYpeOxdSkJKSF1_YtKkuuy8Q | Q167: Відповідає вимогам | S167: грн10 329,00 | T167: UAH | U167: WATCH | V167: =IFERROR(L167/J167,0) | W167: Monitor performance and collect more data. | X167: Cost is below the 250 watch threshold.
A168: average_price | B168: Medium priority | C168: average_price.csv | D168: 1539camogrey | E168: Вейдерси Finntrail Enduro 1539 CamoGrey | F168: 54 | G168: 2130 | H168: 2.54 | I168: 8.23 | J168: 444.24 | K168: 0 | L168: 0 | M168: 0 | N168: 2.74 | O168: 46293.5 | P168: http://t2.gstatic.com/shopping?q=tbn:ANd9GcT4-T_rYCEd53LCOm28u5Jc58K3VJa6sG8JdKx-NBoUah4vjneitnOE1VezM9xt69D4Z0Cr8dny | Q168: Відповідає вимогам | S168: грн16 835,00 | T168: UAH | U168: WATCH | V168: =IFERROR(L168/J168,0) | W168: Monitor performance and collect more data. | X168: Performance is below the scale and keep thresholds.
A169: average_price | B169: Medium priority | C169: average_price.csv | D169: 710008297 | E169: Панель приладів BRP Can-Am Outlander G2 G3 2024+ | F169: 12 | G169: 1365 | H169: 0.88 | I169: 4.06 | J169: 48.75 | K169: 1.01 | L169: 8809.48 | M169: 48.18 | N169: 1.04 | O169: 9174.55 | P169: http://t0.gstatic.com/shopping?q=tbn:ANd9GcS3sZ-DPhFY9SR6szVDzckUF9uMeE-8EyQdsX3ejIpUhaLf4gRAPf1H1MqvY85mY5VJWljNw90 | Q169: Відповідає вимогам | S169: грн19 429,00 | T169: UAH | U169: WATCH | V169: =IFERROR(L169/J169,0) | W169: Monitor performance and collect more data. | X169: Cost is below the 250 watch threshold.
A170: average_price | B170: Medium priority | C170: average_price.csv | D170: 705016269 | E170: Крило заднє праве BRP Can-Am Outlander G2 Max 1000 LTD 2022-2023 | F170: 0 | G170: 15 | H170: 0 | I170: 0 | J170: 0 | K170: 0 | L170: 0 | M170: 0 | N170: 0 | O170: 0 | P170: http://t1.gstatic.com/shopping?q=tbn:ANd9GcTmCi29c9W_x-0dwBcdAcYXPGkm3yU34qgzQXIJQNt4w_3vE18joPLNL1A0Q761hwUN5SJTFQX4 | Q170: Відповідає вимогам | S170: грн22 705,00 | T170: UAH | U170: WATCH | V170: =IFERROR(L170/J170,0) | W170: Monitor performance and collect more data. | X170: Cost is below the 250 watch threshold.
A171: average_price | B171: Medium priority | C171: average_price.csv | D171: 05908 | E171: Розширювачі арок BRP Can-Am Maverick X3 | F171: 0 | G171: 2 | H171: 0 | I171: 0 | J171: 0 | K171: 0 | L171: 0 | M171: 0 | N171: 0 | O171: 0 | P171: http://t1.gstatic.com/shopping?q=tbn:ANd9GcShHBueB9GPi4UVC4HGgH6NhZV7DYUBPy5MQuJWXJMIt7msWW8YvOQ1KxV5cDhtYENU9J3j9Eh_ | Q171: Відповідає вимогам | S171: грн10 238,00 | T171: UAH | U171: WATCH | V171: =IFERROR(L171/J171,0) | W171: Monitor performance and collect more data. | X171: Cost is below the 250 watch threshold.
A172: average_price | B172: Medium priority | C172: average_price.csv | D172: 715010613 | E172: Ричаг передній нижній правий BRP Can-Am Maverick X3 72" | F172: 2 | G172: 278 | H172: 0.72 | I172: 3.4 | J172: 6.8 | K172: 0 | L172: 0 | M172: 0 | N172: 0 | O172: 0 | P172: http://t1.gstatic.com/shopping?q=tbn:ANd9GcTo9ZmzwtnAf5ss9j1o3eaOAM_V1iu9awu3lR654LKfnMsxmz-IeX8-uXSPUnJ0KHQT3GOBoo8 | Q172: Відповідає вимогам | S172: грн17 290,00 | T172: UAH | U172: WATCH | V172: =IFERROR(L172/J172,0) | W172: Monitor performance and collect more data. | X172: Cost is below the 250 watch threshold.
A173: average_price | B173: Medium priority | C173: average_price.csv | D173: 9awa-041021-0yd00 | E173: Крило переднє суцільне CFMoto CForce 800 1000 (Orange) | F173: 0 | G173: 0 | I173: 0 | J173: 0 | K173: 0 | L173: 0 | M173: 0 | N173: 0 | O173: 0 | P173: http://t2.gstatic.com/shopping?q=tbn:ANd9GcQ5N8mKwL2oCMkwWIdZGEjHU6Yr-i3UZNKSrf1LiuWDNDWL_oNA1gf0RrUVN25gRfD5KUVNR9k | Q173: Відповідає вимогам | S173: грн14 560,00 | T173: UAH | U173: WATCH | V173: =IFERROR(L173/J173,0) | W173: Monitor performance and collect more data. | X173: Cost is below the 250 watch threshold.
A174: average_price | B174: Medium priority | C174: average_price.csv | D174: 02976 | E174: Варіатор ведучий в зборі Polaris RZR XP 1000 (14-18), General 1000 (18+) | F174: 12 | G174: 263 | H174: 4.56 | I174: 25.77 | J174: 309.27 | K174: 0 | L174: 0 | M174: 0 | N174: 0 | O174: 0 | P174: http://t0.gstatic.com/shopping?q=tbn:ANd9GcQ9hpWMeBvaezsGaKiMMUDCoI6O2cCc8v71v6k_cNROyLYwR8nioKzF2qv4V_V6TUfbhvkWJow | Q174: Відповідає вимогам | S174: грн14 697,00 | T174: UAH | U174: WATCH | V174: =IFERROR(L174/J174,0) | W174: Monitor performance and collect more data. | X174: Performance is below the scale and keep thresholds.
A175: average_price | B175: Medium priority | C175: average_price.csv | D175: 420684566 | E175: Стартер BRP Can-Am Outlander Renegade G1 G2 G2S, Commander 800 1000, Maverick 1000, Maverick Trail 800 1000, Maverick Sport 1000, Traxter Defender HD8 | F175: 4 | G175: 849 | H175: 0.47 | I175: 10.23 | J175: 40.92 | K175: 0 | L175: 0 | M175: 0 | N175: 0 | O175: 0 | P175: http://t3.gstatic.com/shopping?q=tbn:ANd9GcQ_uRFxxL7DS4khycLdE3WfHJ8vVjhlLhtrM-x8r5YjenwOD5YRYqYCboTzx10gG5WJzODf6Q | Q175: Відповідає вимогам | S175: грн15 834,00 | T175: UAH | U175: WATCH | V175: =IFERROR(L175/J175,0) | W175: Monitor performance and collect more data. | X175: Cost is below the 250 watch threshold.
A176: average_price | B176: Medium priority | C176: average_price.csv | D176: 1532camoshadowblack | E176: Вейдерси Finntrail Athletic 1532 CamoShadowBlack | F176: 3 | G176: 120 | H176: 2.5 | I176: 5.3 | J176: 15.91 | K176: 0 | L176: 0 | M176: 0 | N176: 0 | O176: 0 | P176: http://t1.gstatic.com/shopping?q=tbn:ANd9GcQR6OBWSn6weoD-YUfVrbKmnPhlzK9JXYQz5xYuZSCLwHTq3tnyB26K2frcq8wQw2N34KOIA6K7 | Q176: Відповідає вимогам | S176: грн10 920,00 | T176: UAH | U176: WATCH | V176: =IFERROR(L176/J176,0) | W176: Monitor performance and collect more data. | X176: Cost is below the 250 watch threshold.
A177: average_price | B177: Medium priority | C177: average_price.csv | D177: 715007182 | E177: Кофр LinQ для BRP Can-Am Maverick R (96L) | F177: 6 | G177: 476 | H177: 1.26 | I177: 7.74 | J177: 46.44 | K177: 0.5 | L177: 409.5 | M177: 92.88 | N177: 0.5 | O177: 409.5 | P177: http://t1.gstatic.com/shopping?q=tbn:ANd9GcSIDCLH-gBLRXmhh_KDgbuYqwl0Er-vw3W8GZEHgPGI_GodAQgzN0Z5cF5aUA0NHM7jxlBcRhBh | Q177: Відповідає вимогам | S177: грн25 253,00 | T177: UAH | U177: WATCH | V177: =IFERROR(L177/J177,0) | W177: Monitor performance and collect more data. | X177: Cost is below the 250 watch threshold.
A178: average_price | B178: Medium priority | C178: average_price.csv | D178: 9290780409 | E178: Шолом BRP Can-Am Pura Fade Grey (S) | F178: 0 | G178: 0 | I178: 0 | J178: 0 | K178: 0 | L178: 0 | M178: 0 | N178: 0 | O178: 0 | P178: http://t1.gstatic.com/shopping?q=tbn:ANd9GcTodA1JkgDlj6bBCHunLfADD-dBTQzYlTZKqa46x5CopKBNQKG61KwfdC_0UNVZaSft8aXQVzM | Q178: Відповідає вимогам | S178: грн14 833,00 | T178: UAH | U178: WATCH | V178: =IFERROR(L178/J178,0) | W178: Monitor performance and collect more data. | X178: Cost is below the 250 watch threshold.
A179: average_price | B179: Medium priority | C179: average_price.csv | D179: 02.23500 | E179: Пластиковий захист днища BRP Can-Am Renegade G2S XMR 2019+ | F179: 4 | G179: 356 | H179: 1.12 | I179: 6.69 | J179: 26.74 | K179: 0 | L179: 0 | M179: 0 | N179: 0 | O179: 0 | P179: http://t2.gstatic.com/shopping?q=tbn:ANd9GcT9apFghhFDSKCp-h8eeL2jStBXNC_91uShzZh8yxW5EZGFRZsKNo4ucGWoU16qkrtysX-eUQ | Q179: Відповідає вимогам | S179: грн19 565,00 | T179: UAH | U179: WATCH | V179: =IFERROR(L179/J179,0) | W179: Monitor performance and collect more data. | X179: Cost is below the 250 watch threshold.
A180: average_price | B180: Medium priority | C180: average_price.csv | D180: ab6-ca-8-111 | E180: Піввісь передня ліва BRP Can-Am Outlander 400 500 650 800, Renegade 500 800 | F180: 0 | G180: 37 | H180: 0 | I180: 0 | J180: 0.03 | K180: 0 | L180: 0 | M180: 0 | N180: 0 | O180: 0 | P180: http://t1.gstatic.com/shopping?q=tbn:ANd9GcRSLYBgoZCwlPFXuua4RqGU55pG_EVGz0glwfcm9tyVFChNZ7TPXevVa9rM_Auw-mgIKv0Ddg | Q180: Відповідає вимогам | S180: грн10 329,00 | T180: UAH | U180: WATCH | V180: =IFERROR(L180/J180,0) | W180: Monitor performance and collect more data. | X180: Cost is below the 250 watch threshold.
A181: average_price | B181: Medium priority | C181: average_price.csv | D181: 45014-0369 | E181: Амортизатор передній Kawasaki Brute Force 750 2005-2006 | F181: 0 | G181: 0 | I181: 0 | J181: 0 | K181: 0 | L181: 0 | M181: 0 | N181: 0 | O181: 0 | P181: http://t0.gstatic.com/shopping?q=tbn:ANd9GcQJylokoA9KPffQTrXBFnbpoxIpN5YUYraaedC9TCeq1urdTnHkzm0zgqHQTaVVGs8c8m1BvOY | Q181: Відповідає вимогам | S181: грн23 023,00 | T181: UAH | U181: WATCH | V181: =IFERROR(L181/J181,0) | W181: Monitor performance and collect more data. | X181: Cost is below the 250 watch threshold.
A182: average_price | B182: Medium priority | C182: average_price.csv | D182: 1023240-689 | E182: Тяга задньої підвіски нижня Polaris RZR XP 1000, Ranger XP 1000 2017 (Blue) | F182: 0 | G182: 0 | I182: 0 | J182: 0 | K182: 0 | L182: 0 | M182: 0 | N182: 0 | O182: 0 | P182: http://t0.gstatic.com/shopping?q=tbn:ANd9GcQf6i9AL8y9Y_F-kVbDyNxBGKoKcnLcYedAif_GUmv1rpaxvH9ytQzQfKjgOCauBhaBPEmX5WE | Q182: Відповідає вимогам | S182: грн17 154,00 | T182: UAH | U182: WATCH | V182: =IFERROR(L182/J182,0) | W182: Monitor performance and collect more data. | X182: Cost is below the 250 watch threshold.
A183: average_price | B183: Medium priority | C183: average_price.csv | D183: 9290400207 | E183: Шолом BRP Can-Am Exome Grey (XS) | F183: 0 | G183: 0 | I183: 0 | J183: 0 | K183: 0 | L183: 0 | M183: 0 | N183: 0 | O183: 0 | P183: http://t1.gstatic.com/shopping?q=tbn:ANd9GcRA_YGvlEh6_rZ_pR1804kUWjdtxBJAyNk1xxBw1zG4R0taUs3ERYrkcp3F4N63ULibh2TjA3k | Q183: Відповідає вимогам | S183: грн18 519,00 | T183: UAH | U183: WATCH | V183: =IFERROR(L183/J183,0) | W183: Monitor performance and collect more data. | X183: Cost is below the 250 watch threshold.
A184: average_price | B184: Medium priority | C184: average_price.csv | D184: 420248608 | E184: Грузики варіатора BRP Can-Am Maverick 1000 (13-18), Commander 1000 (18-20) | F184: 0 | G184: 0 | I184: 0 | J184: 0 | K184: 0 | L184: 0 | M184: 0 | N184: 0 | O184: 0 | P184: http://t0.gstatic.com/shopping?q=tbn:ANd9GcRYDA8pLDJW3EuLpVX0MR7LgFqSO9BUYoqSe9M9G9CIR59DGn6pbrcqlSIVF03oyw9CWl9DnhQ | Q184: Відповідає вимогам | S184: грн11 330,00 | T184: UAH | U184: WATCH | V184: =IFERROR(L184/J184,0) | W184: Monitor performance and collect more data. | X184: Cost is below the 250 watch threshold.
A185: average_price | B185: Medium priority | C185: average_price.csv | D185: 431-01027 | E185: Лебідка All Balls 6000 | F185: 0 | G185: 0 | I185: 0 | J185: 0 | K185: 0 | L185: 0 | M185: 0 | N185: 0 | O185: 0 | P185: http://t0.gstatic.com/shopping?q=tbn:ANd9GcT2YzNNkUj2-1AYCAYzl3joEFXHVxbe-RyIGmLV7hwXn9GGjxEBBRh81a_6Pw | Q185: Відповідає вимогам | S185: грн18 428,00 | T185: UAH | U185: WATCH | V185: =IFERROR(L185/J185,0) | W185: Monitor performance and collect more data. | X185: Cost is below the 250 watch threshold.
A186: average_price | B186: Medium priority | C186: average_price.csv | D186: 47-1029 | E186: Паливний насос в зборі BRP Can-Am Outlander 450 570, Renegade 570 | F186: 0 | G186: 0 | I186: 0 | J186: 0 | K186: 0 | L186: 0 | M186: 0 | N186: 0 | O186: 0 | P186: http://t3.gstatic.com/shopping?q=tbn:ANd9GcQgYZ78mXiuFowud0Afb4KgYBhbjV5CuwcQSRtAqY4OHT85wn-wWPRSeYXEd37YJ0rbR_N-nuVr | Q186: Відповідає вимогам | S186: грн12 467,00 | T186: UAH | U186: WATCH | V186: =IFERROR(L186/J186,0) | W186: Monitor performance and collect more data. | X186: Cost is below the 250 watch threshold.
A187: average_price | B187: Medium priority | C187: average_price.csv | D187: 15100-hn2-010 | E187: Масляний насос Honda TRX 500 Rubicon 2001-2014 | F187: 0 | G187: 0 | I187: 0 | J187: 0 | K187: 0 | L187: 0 | M187: 0 | N187: 0 | O187: 0 | P187: http://t2.gstatic.com/shopping?q=tbn:ANd9GcSeGFNxHn75qF_7KRyb2yInECeoLTObUZ7qkicZChrH0hIFQNsIdPmSEDYWeElK3gsEnKrSmuM | Q187: Відповідає вимогам | S187: грн18 928,00 | T187: UAH | U187: WATCH | V187: =IFERROR(L187/J187,0) | W187: Monitor performance and collect more data. | X187: Cost is below the 250 watch threshold.
A188: average_price | B188: Medium priority | C188: average_price.csv | D188: 705402235 | E188: Піввісь передня ліва BRP Can-Am Outlander Renegade G2 G2S 2019+ | F188: 0 | G188: 0 | I188: 0 | J188: 0 | K188: 0 | L188: 0 | M188: 0 | N188: 0 | O188: 0 | P188: http://t1.gstatic.com/shopping?q=tbn:ANd9GcTpWAUE_QL1P7RtDSvDUrhxB8oXTZr251sM4um9NDIZTU5mbQF-Bm7FGwZcBHbWsiv8Nx73T7I | Q188: Відповідає вимогам | S188: грн13 832,00 | T188: UAH | U188: WATCH | V188: =IFERROR(L188/J188,0) | W188: Monitor performance and collect more data. | X188: Cost is below the 250 watch threshold.
A189: average_price | B189: Medium priority | C189: average_price.csv | D189: 703500994 | E189: Карданний вал задній BRP Can-Am Maverick​ 1000 2013-2018 | F189: 0 | G189: 0 | I189: 0 | J189: 0 | K189: 0 | L189: 0 | M189: 0 | N189: 0 | O189: 0 | P189: http://t3.gstatic.com/shopping?q=tbn:ANd9GcSCZcho0YU-KGdkqtKOmADv03uQAiyON8gdKqeSUdsEvrcmWM8VWpubcE5eu3TbFrtREHvqL3c | Q189: Відповідає вимогам | S189: грн16 926,00 | T189: UAH | U189: WATCH | V189: =IFERROR(L189/J189,0) | W189: Monitor performance and collect more data. | X189: Cost is below the 250 watch threshold.
A190: average_price | B190: Medium priority | C190: average_price.csv | D190: 710007301 | E190: Блок перемикачів на руль лівий BRP Can-Am Outlander G3 G3L | F190: 0 | G190: 0 | I190: 0 | J190: 0 | K190: 0 | L190: 0 | M190: 0 | N190: 0 | O190: 0 | P190: http://t1.gstatic.com/shopping?q=tbn:ANd9GcQF1cJNQCXsYzASV6oVMoD_ZnuQt_jRPA9iLrVl0jQHtplebks8bPkmYQL1lDug9Ihn-OqGoAU5 | Q190: Відповідає вимогам | S190: грн15 652,00 | T190: UAH | U190: WATCH | V190: =IFERROR(L190/J190,0) | W190: Monitor performance and collect more data. | X190: Cost is below the 250 watch threshold.
...

Sheet KEEP
A1: SKU | B1: Campaign | C1: Product | D1: Clicks | E1: Cost | F1: Conversions | G1: Revenue | H1: ROAS | I1: Reason
A2: 05434 | B2: high_price | C2: Комплект рестайлінгу BRP Can-Am Outlander G2 | D2: 1603 | E2: 3548.54 | F2: 3 | G2: 13925 | H2: =IFERROR(G2/E2,0) | I2: At least 2 conversions.
A3: 60s-01 | B3: average_price | C3: Мотогарнітура Sena 60S | D3: 151 | E3: 3784.85 | F3: 2.05 | G3: 18433.92 | H3: =IFERROR(G3/E3,0) | I3: At least 2 conversions.
A4: 5hy0-2803a0 | B4: low_price | C4: Пильник ШРУСа задній зовнішній CFMoto CForce 800 1000, UForce 1000, ZForce 950 1000 | D4: 30 | E4: 163.06 | F4: 2.5 | G4: 3159.25 | H4: =IFERROR(G4/E4,0) | I4: At least 2 conversions.
A5: 860202529 | B5: low_price | C5: Носик-лійка до каністр LinQ для BRP Can-Am, Ski-Doo, Sea-Doo | D5: 11 | E5: 208.8 | F5: 2.74 | G5: 4040.26 | H5: =IFERROR(G5/E5,0) | I5: At least 2 conversions.
A6: 9awa-260014 | B6: low_price | C6: Розширювач арки задній правий CFMoto CForce 850 1000 | D6: 40 | E6: 201.15 | F6: 2.02 | G6: 3399.4 | H6: =IFERROR(G6/E6,0) | I6: At least 2 conversions.
A7: 105781 | B7: low_price | C7: Масло для редукторів Motul HD 80W90 (1L) | D7: 131 | E7: 463.98 | F7: 3.01 | G7: 1357.37 | H7: =IFERROR(G7/E7,0) | I7: At least 2 conversions.
A8: 420256188 | B8: low_price | C8: Масляний фільтр BRP Can-Am, Ski-Doo, Sea-Doo; CFMoto UForce 500 600 800 1000, ZForce 500 800 950 1000; Hisun 800 1000 | D8: 34 | E8: 316.25 | F8: 2.25 | G8: 2388.33 | H8: =IFERROR(G8/E8,0) | I8: At least 2 conversions.
A9: 102986 | B9: low_price | C9: Мастило для повітряних фільтрів Motul A2 (400ml) | D9: 188 | E9: 1921.69 | F9: 8 | G9: 8153 | H9: =IFERROR(G9/E9,0) | I9: At least 2 conversions.
A10: 422280366 | B10: low_price | C10: Ремінь варіатора BRP Can-Am Outlander Renegade G1 G2 G2L G2S, Maverick 1000, Commander 800 1000 | D10: 39 | E10: 281.29 | F10: 2.01 | G10: 4000.93 | H10: =IFERROR(G10/E10,0) | I10: At least 2 conversions.

Sheet WATCH
A1: SKU | B1: Campaign | C1: Product | D1: Clicks | E1: Cost | F1: Conversions | G1: Revenue | H1: ROAS | I1: Reason
A2: 13031-0983 | B2: high_price | C2: Колінвал Kawasaki Teryx 800​ 2014+ | D2: 0 | E2: 0 | F2: 0 | G2: 0 | H2: =IFERROR(G2/E2,0) | I2: Cost is below the 300 watch threshold.
A3: 715009472 | B3: high_price | C3: Кофр LinQ для BRP Can-Am Outlander G3 G3L (139L) | D3: 35 | E3: 392.91 | F3: 0 | G3: 0 | H3: =IFERROR(G3/E3,0) | I3: Performance is below the scale and keep thresholds.
A4: 420219746 | B4: high_price | C4: Колінвал BRP Can-Am Outlander 570 650 800 850, Renegade 650 800 850, Commander 800 | D4: 0 | E4: 0 | F4: 0 | G4: 0 | H4: =IFERROR(G4/E4,0) | I4: Cost is below the 300 watch threshold.
A5: 715007110 | B5: high_price | C5: Комплект шноркеля BRP Can-Am Maverick X3 2020+ | D5: 124 | E5: 661.32 | F5: 0 | G5: 0 | H5: =IFERROR(G5/E5,0) | I5: Performance is below the scale and keep thresholds.
A6: 715005481 | B6: high_price | C6: Глушник Yoshimura для BRP Can-Am Renegade G2S | D6: 38 | E6: 276.76 | F6: 0.96 | G6: 4201.38 | H6: =IFERROR(G6/E6,0) | I6: Cost is below the 300 watch threshold.
A7: 709401608 | B7: high_price | C7: Підсилювач керма BRP Can-Am Outlander Renegade G1 G2 G2L G2S 2010-2017 | D7: 19 | E7: 68.52 | F7: 1 | G7: 62017 | H7: =IFERROR(G7/E7,0) | I7: Cost is below the 300 watch threshold.
A8: 12100-hr0-f00 | B8: high_price | C8: Циліндр двигуна Honda TRX 500 Foreman (12-19), 500 Rubicon (15-19), SXS 500 Pioneer (15+) | D8: 0 | E8: 0 | F8: 0 | G8: 0 | H8: =IFERROR(G8/E8,0) | I8: Cost is below the 300 watch threshold.
A9: 707602827 | B9: high_price | C9: Глушник BRP Can-Am Maverick X3 | D9: 8 | E9: 53.76 | F9: 0 | G9: 0 | H9: =IFERROR(G9/E9,0) | I9: Cost is below the 300 watch threshold.
A10: 12200-hn5-m00 | B10: high_price | C10: Головка блоку циліндра Honda TRX 350 Rancher 2003-2006 | D10: 2 | E10: 18.38 | F10: 0 | G10: 0 | H10: =IFERROR(G10/E10,0) | I10: Cost is below the 300 watch threshold.
A11: 26000-hl1-a01 | B11: high_price | C11: Гідротрансформатор Honda TRX 680 Rincon, MUV 700 Big Red, SXS 700 Pioneer | D11: 0 | E11: 0 | F11: 0 | G11: 0 | H11: =IFERROR(G11/E11,0) | I11: Cost is below the 300 watch threshold.
A12: 715008859 | B12: high_price | C12: Вітрове скло BRP Can-Am Maverick X3 | D12: 44 | E12: 58.81 | F12: 0 | G12: 0 | H12: =IFERROR(G12/E12,0) | I12: Cost is below the 300 watch threshold.
A13: 706202170 | B13: high_price | C13: Амортизатор передній BRP Can-Am Outlander XMR 570 650 850 1000 2015-2016 | D13: 9 | E13: 41.83 | F13: 0 | G13: 0 | H13: =IFERROR(G13/E13,0) | I13: Cost is below the 300 watch threshold.
... A5468: we271070 | B5468: low_price | C5468: Кулак передній зовнішній Honda TRX 350 Rancher (00-05), 400 Rancher (04-07), 680 Rincon (06-07) | D5468: 0 | E5468: 0 | F5468: 0 | G5468: 0 | H5468: =IFERROR(G5468/E5468,0) | I5468: Cost is below the 120 watch threshold.

Sheet PAUSE
A1: SKU | B1: Campaign | C1: Product | D1: Clicks | E1: Cost | F1: Conversions | G1: Revenue | H1: ROAS | I1: Reason
A2: 50s-10d | B2: average_price | C2: Мотогарнітура Sena 50S Dual | D2: 23 | E2: 733.76 | F2: 0 | G2: 0 | H2: =IFERROR(G2/E2,0) | I2: Cost of at least 450 with no more than 0 conversions.
A3: 9ayv-806100-2a00 | B3: average_price | C3: Кофр задній CFMoto CForce 850 1000 (115L) | D3: 61 | E3: 473.9 | F3: 0 | G3: 0 | H3: =IFERROR(G3/E3,0) | I3: Cost of at least 450 with no more than 0 conversions.
A4: 04161 | B4: average_price | C4: Трапи алюмінієві складні для квадроцикла або баггі | D4: 35 | E4: 483.68 | F4: 0 | G4: 0 | H4: =IFERROR(G4/E4,0) | I4: Cost of at least 450 with no more than 0 conversions.
A5: 715003462 | B5: average_price | C5: Бампер задній Rancher для BRP Can-Am Outlander G2 G2L | D5: 350 | E5: 1177.19 | F5: 0 | G5: 0 | H5: =IFERROR(G5/E5,0) | I5: Cost of at least 450 with no more than 0 conversions.
A6: 0180-055000-0004 | B6: average_price | C6: Ремінь варіатора CFMoto CForce 400 500 600, ZForce 500 600, UForce 500 600 | D6: 70 | E6: 591.49 | F6: 0 | G6: 0 | H6: =IFERROR(G6/E6,0) | I6: Cost of at least 450 with no more than 0 conversions.
A7: 108664 | B7: low_price | C7: Універсальна пластична змазка Motul Tech Grease 300 (400g) | D7: 36 | E7: 226.78 | F7: 0 | G7: 0 | H7: =IFERROR(G7/E7,0) | I7: Cost of at least 220 with no more than 0 conversions.
A8: etx20hl-bs | B8: low_price | C8: Акумулятор Exide YTX20HL-BS | D8: 19 | E8: 350.57 | F8: 0 | G8: 0 | H8: =IFERROR(G8/E8,0) | I8: Cost of at least 220 with no more than 0 conversions.
A9: 19-1008 | B9: low_price | C9: Хрестовина карданного валу BRP Can-Am; Polaris | D9: 26 | E9: 283.17 | F9: 0 | G9: 0 | H9: =IFERROR(G9/E9,0) | I9: Cost of at least 220 with no more than 0 conversions.
A10: 06192 | B10: low_price | C10: Радіатор BRP Can-Am Outlander Renegade G2 G2L G2S | D10: 19 | E10: 221.36 | F10: 0 | G10: 0 | H10: =IFERROR(G10/E10,0) | I10: Cost of at least 220 with no more than 0 conversions.
A11: 107672 | B11: low_price | C11: Мінеральне моторне масло Motul 3000 4T 10W40 (1L) | D11: 40 | E11: 375.32 | F11: 0 | G11: 0 | H11: =IFERROR(G11/E11,0) | I11: Cost of at least 220 with no more than 0 conversions.
A12: 0986fa1071 | B12: low_price | C12: Акумулятор Bosch YTX20L-BS | D12: 30 | E12: 394.67 | F12: 0 | G12: 0 | H12: =IFERROR(G12/E12,0) | I12: Cost of at least 220 with no more than 0 conversions.
A13: etm00335900 | B13: low_price | C13: Шина Maxxis Bighorn 30×10-14 | D13: 18 | E13: 259.28 | F13: 0 | G13: 0 | H13: =IFERROR(G13/E13,0) | I13: Cost of at least 220 with no more than 0 conversions.
... A24: bdt95 | B24: low_price | C24: Інструмент для затяжки та обрізання хомутів | D24: 15 | E24: 275 | F24: 0 | G24: 0 | H24: =IFERROR(G24/E24,0) | I24: Cost of at least 220 with no more than 0 conversions.

Sheet SCALE
A1: SKU | B1: Campaign | C1: Product | D1: Clicks | E1: Cost | F1: Conversions | G1: Revenue | H1: ROAS | I1: Reason
A2: 715009471 | B2: high_price | C2: Кофр LinQ для BRP Can-Am Outlander G3 G3L (145L) | D2: 51 | E2: 669.55 | F2: 1.64 | G2: 35521.89 | H2: =IFERROR(G2/E2,0) | I2: ROAS of at least 1200% with conversion value of at least 5000.
A3: 04647 | B3: high_price | C3: Комплект виносу радіатора та шноркелів BRP Can-Am Outlander G3 | D3: 72 | E3: 493.06 | F3: 0.87 | G3: 26842 | H3: =IFERROR(G3/E3,0) | I3: ROAS of at least 1200% with conversion value of at least 5000.
A4: 9dqv-806100-3001 | B4: average_price | C4: Кофр задній CFMoto CForce 450 520 (100L) | D4: 212 | E4: 1679 | F4: 2.99 | G4: 34360.55 | H4: =IFERROR(G4/E4,0) | I4: ROAS of at least 900% with conversion value of at least 5000.
A5: 9290400607 | B5: average_price | C5: Шолом BRP Can-Am Exome Grey (M) | D5: 111 | E5: 957.84 | F5: 2.01 | G5: 23823.45 | H5: =IFERROR(G5/E5,0) | I5: ROAS of at least 900% with conversion value of at least 5000.
A6: 860202246 | B6: average_price | C6: Каністра LinQ для BRP Can-Am, Ski-Doo, Sea-Doo | D6: 39 | E6: 497.56 | F6: 3.85 | G6: 10055.44 | H6: =IFERROR(G6/E6,0) | I6: ROAS of at least 900% with conversion value of at least 5000.
A7: 710007609 | B7: average_price | C7: Блок перемикачів на руль лівий BRP Can-Am Outlander G3 G3L | D7: 27 | E7: 302.1 | F7: 1 | G7: 13725 | H7: =IFERROR(G7/E7,0) | I7: ROAS of at least 900% with conversion value of at least 5000.
A8: 0jya-052000 | B8: average_price | C8: Варіатор ведений в зборі CFMoto CForce 800 1000, UForce 1000, ZForce 1000 | D8: 32 | E8: 330.67 | F8: 1.51 | G8: 9702.98 | H8: =IFERROR(G8/E8,0) | I8: ROAS of at least 900% with conversion value of at least 5000.
A9: 9779493 | B9: low_price | C9: Синтетичне моторне масло BRP XPS 4T 5W40 (4L) | D9: 94 | E9: 1009.15 | F9: 12.77 | G9: 73271 | H9: =IFERROR(G9/E9,0) | I9: ROAS of at least 700% with conversion value of at least 5000.
A10: 19g3982 | B10: low_price | C10: Ремінь варіатора Polaris Sportsman 500 570 700 800, Ranger 500 800, RZR 800 | D10: 26 | E10: 165.8 | F10: 3.16 | G10: 11392.13 | H10: =IFERROR(G10/E10,0) | I10: ROAS of at least 700% with conversion value of at least 5000.
A11: 2520799 | B11: low_price | C11: Масляний фільтр Polaris Sportsman 300 325 400 450 500 550 570 850 1000, Scrambler 500 850 1000, RZR 1000, RZR Pro, Ranger 400 425 500, Hawkeye 330 400 | D11: 24 | E11: 124.26 | F11: 2.33 | G11: 6604.27 | H11: =IFERROR(G11/E11,0) | I11: ROAS of at least 700% with conversion value of at least 5000.
A12: 6p0947 | B12: low_price | C12: Шина ITP Terra Hook 32×10-14 8PR | D12: 13 | E12: 173.81 | F12: 2 | G12: 10979.28 | H12: =IFERROR(G12/E12,0) | I12: ROAS of at least 700% with conversion value of at least 5000.
A13: hff7011 | B13: low_price | C13: Повітряний фільтр Polaris Sportsman 335 400 450 500 550 570 600 700 800 850 1000, Scrambler 500 850 1000, Magnum 325 500, Hawkeye 325 400, Xpedition | D13: 7 | E13: 147.18 | F13: 1.37 | G13: 8922.28 | H13: =IFERROR(G13/E13,0) | I13: ROAS of at least 700% with conversion value of at least 5000.
... A35: 705403534 | B35: low_price | C35: Колісний диск передній BRP Can-Am Outlander G3L | D35: 15 | E35: 135.06 | F35: 0.33 | G35: 5702.68 | H35: =IFERROR(G35/E35,0) | I35: ROAS of at least 700% with conversion value of at least 5000.

Sheet Top Winners
A1: SKU | B1: Campaign | C1: Product | D1: Clicks | E1: Cost | F1: Conversions | G1: Revenue | H1: ROAS | I1: Reason
A2: 707800724 | B2: low_price | C2: Корпус повітряного фільтра BRP Can-Am Outlander Renegade G2 G2L G2S | D2: 1 | E2: 0.01 | F2: 1 | G2: 5005 | H2: =IFERROR(G2/E2,0) | I2: Cost is below the 120 watch threshold.
A3: cpr7ea-9 | B3: low_price | C3: Свічка запалювання Yamaha Grizzly Kodiak Rhino Viking Wolverine 700 | D3: 1 | E3: 0.01 | F3: 0.5 | G3: 182 | H3: =IFERROR(G3/E3,0) | I3: Cost is below the 120 watch threshold.
A4: 708301212 | B4: low_price | C4: Верхня кришка заднього бардачка BRP Can-Am Outlander G2 | D4: 4 | E4: 22.05 | F4: 1 | G4: 68705 | H4: =IFERROR(G4/E4,0) | I4: Cost is below the 120 watch threshold.
A5: 2206367 | B5: low_price | C5: Регулятор напруги Polaris RZR 900 (13-14), RZR XP 1000 (14-16) | D5: 1 | E5: 1.3 | F5: 1 | G5: 4004 | H5: =IFERROR(G5/E5,0) | I5: Cost is below the 120 watch threshold.
A6: 24611-hp5-010 | B6: low_price | C6: Вал перемикання передач Honda TRX 420 Rancher​ 2007+ | D6: 3 | E6: 1.93 | F6: 1 | G6: 5689 | H6: =IFERROR(G6/E6,0) | I6: Cost is below the 120 watch threshold.
A7: 9ds#-104100-6000 | B7: low_price | C7: Рульова тяга в зборі CFMoto CForce 625 2020+ | D7: 5 | E7: 42.6 | F7: 1.16 | G7: 100035.55 | H7: =IFERROR(G7/E7,0) | I7: Cost is below the 120 watch threshold.
A8: tm01007100 | B8: low_price | C8: Шина Maxxis Bighorn 3.0 27×9-14 | D8: 11 | E8: 86.89 | F8: 4.07 | G8: 155851.61 | H8: =IFERROR(G8/E8,0) | I8: Cost is below the 120 watch threshold.
A9: 39007-0177-10 | B9: low_price | C9: Ричаг передній нижній правий Kawasaki Brute Force 750​ | D9: 2 | E9: 2.97 | F9: 1 | G9: 5051 | H9: =IFERROR(G9/E9,0) | I9: Cost is below the 120 watch threshold.
A10: 7518654 | B10: low_price | C10: Шпилька ступиці колеса Polaris RZR 570 800 | D10: 1 | E10: 3.52 | F10: 2 | G10: 5965 | H10: =IFERROR(G10/E10,0) | I10: Cost is below the 120 watch threshold.
A11: 715009796 | B11: high_price | C11: Модуль управління аксесуарами BRP Can-Am Maverick X3, Maverick R | D11: 6 | E11: 16.12 | F11: 0.63 | G11: 25072.5 | H11: =IFERROR(G11/E11,0) | I11: Cost is below the 300 watch threshold.

Sheet Top Losers
A1: SKU | B1: Campaign | C1: Product | D1: Clicks | E1: Cost | F1: Conversions | G1: Revenue | H1: ROAS | I1: Reason
A2: 715003462 | B2: average_price | C2: Бампер задній Rancher для BRP Can-Am Outlander G2 G2L | D2: 350 | E2: 1177.19 | F2: 0 | G2: 0 | H2: =IFERROR(G2/E2,0) | I2: Cost of at least 450 with no more than 0 conversions.
A3: 50s-10d | B3: average_price | C3: Мотогарнітура Sena 50S Dual | D3: 23 | E3: 733.76 | F3: 0 | G3: 0 | H3: =IFERROR(G3/E3,0) | I3: Cost of at least 450 with no more than 0 conversions.
A4: 715004284 | B4: high_price | C4: Світлодіодна оптика Baja для BRP Can-Am Outlander G2 | D4: 104 | E4: 672.45 | F4: 0 | G4: 0 | H4: =IFERROR(G4/E4,0) | I4: Performance is below the scale and keep thresholds.
A5: 715007110 | B5: high_price | C5: Комплект шноркеля BRP Can-Am Maverick X3 2020+ | D5: 124 | E5: 661.32 | F5: 0 | G5: 0 | H5: =IFERROR(G5/E5,0) | I5: Performance is below the scale and keep thresholds.
A6: 105888 | B6: low_price | C6: Напівсинтетичне моторне масло для снігоходів Motul Snowpower 2T (4L) | D6: 39 | E6: 654.26 | F6: 0 | G6: 0 | H6: =IFERROR(G6/E6,0) | I6: Cost of at least 220 with no more than 0 conversions.
A7: agm12-31 | B7: low_price | C7: Акумулятор Exide AGM12-31 для Polaris | D7: 27 | E7: 652.35 | F7: 0 | G7: 0 | H7: =IFERROR(G7/E7,0) | I7: Cost of at least 220 with no more than 0 conversions.
A8: 715007272 | B8: high_price | C8: Спортивний дах BRP Can-Am Maverick Sport Max 1000, Commander Max 700 1000 | D8: 271 | E8: 605.22 | F8: 0 | G8: 0 | H8: =IFERROR(G8/E8,0) | I8: Performance is below the scale and keep thresholds.
A9: 0180-055000-0004 | B9: average_price | C9: Ремінь варіатора CFMoto CForce 400 500 600, ZForce 500 600, UForce 500 600 | D9: 70 | E9: 591.49 | F9: 0 | G9: 0 | H9: =IFERROR(G9/E9,0) | I9: Cost of at least 450 with no more than 0 conversions.
A10: 04161 | B10: average_price | C10: Трапи алюмінієві складні для квадроцикла або баггі | D10: 35 | E10: 483.68 | F10: 0 | G10: 0 | H10: =IFERROR(G10/E10,0) | I10: Cost of at least 450 with no more than 0 conversions.
A11: 9ayv-806100-2a00 | B11: average_price | C11: Кофр задній CFMoto CForce 850 1000 (115L) | D11: 61 | E11: 473.9 | F11: 0 | G11: 0 | H11: =IFERROR(G11/E11,0) | I11: Cost of at least 450 with no more than 0 conversions.
